Workbook
Name Beg_Bal: #REF!
Name dep: 'FINAL REPORT'!$A$183:$C$232
Name drscrs: 'FINAL REPORT'!$A$149:$C$178
Name ELIGIBILITY_FOR_BANK_OVERDRAFT: #REF!
Name End_Bal: '[1]Loan Calculator'!$I$18:$I$377
Name Extra_Pay: #REF!
Name Header_Row: ROW('[1]Loan Calculator'!$A$17:$IV$17)
Name Int: #REF!
Name Interest_Rate: '[1]Loan Calculator'!$D$5
Name Last_Row: IF(Values_Entered,Header_Row+Number_of_Payments,Header_Row)
Name Loan_Amount: '[1]Loan Calculator'!$D$4
Name Loan_Start: '[1]Loan Calculator'!$D$7
Name Loan_Years: '[1]Loan Calculator'!$D$6
Name ns: 'FINAL REPORT'!$A$59:$C$101
Name Number_of_Payments: MATCH(0.01,End_Bal,-1)+1
Name Pay_Num: #REF!
Name pl: #REF!
Name Princ: #REF!
Name profitloss: 'FINAL REPORT'!$A$27:$C$54
Name RMCONS: #REF!
Name Sched_Pay: #REF!
Name Scheduled_Extra_Payments: #REF!
Name Scheduled_Monthly_Payment: #REF!
Name Total_Pay: #REF!
Name Values_Entered: IF(Loan_Amount*Interest_Rate*Loan_Years*Loan_Start>0,1,0)
Name wc: 'FINAL REPORT'!$A$4:$C$17

Sheet INFO PAGE
A2: PROJECT REPORT DETAILS
A5: 1) | B5: Full Name | C5: : | D5: MRS.TANUJA SINGH
A8: 2) | B8: Nature of Business | C8: : | D8: WORKS & LABOUR CONTRACTORS
A11: 3) | B11: Name Of Business | C11: : | D11: M/S SHREE ENTERPRISES
A13: 4) | B13: Address Of Business | C13: : | D13: BLDG NO.2, A WING, BLOCK NO 20,
D14: VISHRAM TOWER, SHREE NAGA
D15: THANE - 400604
D16: MAHARASHTRA
A19: 5) | B19: Nature of facilities required | C19: : | D19: TERM LOAN OF RS. 35 LACS
A21: 6) | B21: Primary Security | C21: : | D21: RESIDENTIAL PREMISES AT ASHAR AXIS,THANE

Sheet FRONT PAGE

Sheet FINAL REPORT
A2: M/S PHARMACY EXPRESS
A4: ELIGIBILITY FOR BANK CC
A6: Particulars | B6: 31 Mar,23 | C6: 31 Mar,24 | D6: 31 Mar,25 | E6: 31 Mar,26 | F6: 31 Mar,27
B7: PROVISIONAL | C7: PROJECTED | D7: PROJECTED | E7: PROJECTED | F7: PROJECTED
A8: Stock | B8: 24713.98 | C8: =C33 -> 0 | D8: 10893912 | E8: 9020159.5 | F8: 9541324.3
A9: Debtors | B9: 0 | C9: 9689299 | D9: 10744681 | E9: 10983452 | F9: 10063750
A10: Gross Working Capital | B10: =SUM(B8:B9) -> 24713.98 | C10: 21964689 | D10: 21638593 | E10: 20003611 | F10: 19605074
A11: Less: Creditors & O/s exp. | B11: 74132.14 | C11: 4229181.2 | D11: 2536938.5 | E11: 2917479.3 | F11: 3459787.2
A12: Net Working Capital | B12: =B10-B11 -> -49418.16 | C12: 17735508 | D12: 19101655 | E12: 17086132 | F12: 16145287
A13: Less: Margin @ 25% | B13: =B12*25% -> -12354.54 | C13: 4433877 | D13: 4775413.7 | E13: 4271532.9 | F13: 4036321.8
A14: Eligibility For CC (As per Working Capital Basis) | B14: 0 | C14: 13301631 | D14: 14326241 | E14: 12814599 | F14: 12108965
A15: Eligibility For CC (As per Sales Basis) | B15: 0 | C15: 11583813 | D15: 8715130 | E15: 10022399 | F15: 11225087
A16: CC Applied For | B16: 0 | C16: 2000000 | D16: 2000000 | E16: 2000000 | F16: 2000000
A17: Interest @ 12.00% * | B17: 0 | C17: =C16*12/100*1/12 -> 20000 | D17: =D16*12% -> 240000 | E17: =E16*12% -> 240000 | F17: =F16*12% -> 240000
A18: Factor applied for actual debit of interest to CC account | B18: 1 | C18: 1 | D18: 1 | E18: 1 | F18: 1
A24: ='INFO PAGE'!D11 -> M/S SHREE ENTERPRISES
A27: PROJECTED PROFIT & LOSS ACCOUNT
A29: Particulars | B29: 31 Mar,26 | C29: 31 Mar,27 | D29: 31 Mar,28 | E29: 31 Mar,29 | F29: 32 Mar,30 | G29: 32 Mar,31 | H29: 33 Mar,32 | I29: 33 Mar,33 | J29: 34 Mar,34 | K29: 34 Mar,35 | L29: 34 Mar,36
B30: PROVISIONAL | C30: PROJECTED | D30: PROJECTED | E30: PROJECTED | F30: PROJECTED | G30: PROJECTED | H30: PROJECTED | I30: PROJECTED | J30: PROJECTED | K30: PROJECTED | L30: PROJECTED
A32: Sale of Works Contract Service (i) | B32: 74644510 | C32: =B32*1.1 -> 82108961 | D32: =C32*1.08 -> 88677678 | E32: =D32*1.08 -> 95771892 | F32: =E32*1.13 -> 1.0822224e+08 | G32: =F32*1.15 -> 1.2445557e+08 | H32: =G32*1.11 -> 1.3814569e+08 | I32: =H32*1.12 -> 1.5472317e+08 | J32: =I32*1.13 -> 1.7483718e+08 | K32: =J32*1.1 -> 1.923209e+08 | L32: =K32*1.1 -> 2.1155299e+08
A33: Add: Closing Stock as at 31st March | B33: 0 | C33: 0 | D33: =C33*1.1 -> 0 | E33: =D33*1.1 -> 0 | F33: =E33*1.1 -> 0 | G33: =F33*1.1 -> 0 | H33: =G33*1.1 -> 0 | I33: =H33*1.1 -> 0 | J33: =I33*1.1 -> 0 | K33: =J33*1.1 -> 0 | L33: =K33*1.1 -> 0
A34: (A) | B34: =SUM(B32:B33) -> 74644510 | C34: =SUM(C32:C33) -> 82108961 | D34: =SUM(D32:D33) -> 88677678 | E34: =SUM(E32:E33) -> 95771892 | F34: =SUM(F32:F33) -> 1.0822224e+08 | G34: =SUM(G32:G33) -> 1.2445557e+08 | H34: =SUM(H32:H33) -> 1.3814569e+08 | I34: =SUM(I32:I33) -> 1.5472317e+08 | ... L34: =SUM(L32:L33) -> 2.1155299e+08
A36: Less: Purchases of Goods | B36: =58872474-1522664 -> 57349810 | C36: =C32*76% -> 62402810 | D36: =D32*76.5% -> 67838424 | E36: =E32*76.5% -> 73265497 | F36: =F32*77% -> 83331123 | G36: =G32*77% -> 95830792 | H36: =H32*76.7% -> 1.0595774e+08 | I36: =I32*76.7% -> 1.1867267e+08 | J36: =J32*76.7% -> 1.3410012e+08 | K36: =K32*76.7% -> 1.4751013e+08 | L36: =L32*76.7% -> 1.6226114e+08
A37: Labour Charges & Salary | B37: =1522664+10942979 -> 12465643 | C37: =C34*17% -> 13958523 | D37: =D34*16.7% -> 14809172 | E37: =E34*17% -> 16281222 | F37: =F34*16.8% -> 18181336 | G37: =G34*17% -> 21157448 | H37: =H34*17% -> 23484767 | I37: =I34*16.8% -> 25993492 | J37: =J34*16.9% -> 29547484 | K37: =K34*16.7% -> 32117590 | L37: =L34*16.8% -> 35540902
A38: (B) | B38: =SUM(B36:B37) -> 69815453 | C38: =SUM(C36:C37) -> 76361334 | D38: =SUM(D36:D37) -> 82647596 | E38: =SUM(E36:E37) -> 89546719 | F38: =SUM(F36:F37) -> 1.0151246e+08 | G38: =SUM(G36:G37) -> 1.1698824e+08 | H38: =SUM(H36:H37) -> 1.2944251e+08 | I38: =SUM(I36:I37) -> 1.4466616e+08 | ... L38: =SUM(L36:L37) -> 1.9780205e+08
A40: Gross Profit C=(A-B) | B40: =B34-B38 -> 4829057 | C40: =C34-C38 -> 5747627.3 | D40: =D34-D38 -> 6030082.1 | E40: =E34-E38 -> 6225173 | F40: =F34-F38 -> 6709778.8 | G40: =G34-G38 -> 7467334.4 | H40: =H34-H38 -> 8703178.3 | I40: =I34-I38 -> 10057006 | ... L40: =L34-L38 -> 13750944
A41: % of Gross Profit C/i | B41: =B40/B34% -> 6.4694068 | C41: =C40/C34% -> 7 | D41: =D40/D34% -> 6.8 | E41: =E40/E34% -> 6.5 | F41: =F40/F34% -> 6.2 | G41: =G40/G34% -> 6 | H41: =H40/H34% -> 6.3 | I41: =I40/I34% -> 6.5 | ... L41: =L40/L34% -> 6.5
A43: Less: Operating Expenses
A44: Administration, Selling and Distribution Expenses (See Schedule 1) | B44: ='SCH 2'!B23 -> 2413055 | C44: ='SCH 2'!C23 -> 2770657.4 | D44: ='SCH 2'!D23 -> 3040457.7 | E44: ='SCH 2'!E23 -> 3336674.5 | F44: ='SCH 2'!F23 -> 3661905.4 | G44: ='SCH 2'!G23 -> 4273499.3 | H44: ='SCH 2'!H23 -> 4691050.3 | I44: ='SCH 2'!I23 -> 5149593.7 | ... L44: ='SCH 2'!L23 -> 6813605.9
A45: TOTAL OPERATING EXP. | D45: 1836636.9 | E45: 2007831.9 | F45: 2208615.1
A46: NET PROFIT BEFORE DEP and INT | B46: =B40-B44 -> 2416002 | C46: =C40-C44 -> 2976969.9 | D46: =D40-D44 -> 2989624.4 | E46: =E40-E44 -> 2888498.5 | F46: =F40-F44 -> 3047873.3 | G46: =G40-G44 -> 3193835.1 | H46: =H40-H44 -> 4012128 | I46: =I40-I44 -> 4907412.3 | ... L46: =L40-L44 -> 6937338.4
A47: Interest on CC & Term Loan | B47: 295608 | C47: =EMI!J23+OD!E11 -> 485423.67 | D47: =EMI!J35+OD!E12 -> 611762.23 | E47: =EMI!J47+OD!E13 -> 559424.31 | F47: =EMI!J59+OD!E14 -> 503048.1 | G47: =EMI!J82+OD!E15 -> 376395.81 | H47: =EMI!J94+OD!E16 -> 311792.79 | I47: =EMI!J106+OD!E17 -> 246584.94 | J47: =EMI!J118+OD!E18 -> 175526.09 | K47: =EMI!J130+OD!E19 -> 97474.012 | L47: =EMI!J124+OD!E20+EMI!J130 -> 90929.177
A48: NET PROFIT BEFORE DEP | B48: =B46-B47 -> 2120394 | C48: =C46-C47 -> 2491546.2 | D48: =D46-D47 -> 2377862.2 | E48: =E46-E47 -> 2329074.2 | F48: =F46-F47 -> 2544825.2 | G48: =G46-G47 -> 2817439.3 | H48: =H46-H47 -> 3700335.2 | I48: =I46-I47 -> 4660827.4 | ... L48: =L46-L47 -> 6846409.2
A49: Less: Depreciation | B49: =B226 -> 32524.2 | C49: =C226 -> 51395.57 | D49: =D226 -> 65061.234 | E49: =E226 -> 51567.674 | F49: =F226 -> 41720.804 | G49: =G226 -> 34319.051 | H49: =H226 -> 47464.109 | I49: =I226 -> 40111.831 | ... L49: =L226 -> 24794.162
A50: NET PROFIT BEFORE TAX | B50: =B48-B49 -> 2087869.8 | C50: =C48-C49 -> 2440150.6 | D50: =D48-D49 -> 2312801 | E50: =E48-E49 -> 2277506.5 | F50: =F48-F49 -> 2503104.4 | G50: =G48-G49 -> 2783120.3 | H50: =H48-H49 -> 3652871.1 | I50: =I48-I49 -> 4620715.5 | ... L50: =L48-L49 -> 6821615
A51: Less: Income Tax | B51: =(B50-2000000)*26%+208000 -> 230846.15 | C51: =(C50-2400000)*31.2%+312000 -> 324527 | D51: =(2400000-D50)*26%+208000 -> 230671.75 | E51: =(2400000-E50)*26%+208000 -> 239848.32 | F51: =(F50-2400000)*31.2%+312000 -> 344168.58 | G51: =(G50-2400000)*31.2%+312000 -> 431533.52 | H51: =(H50-2400000)*31.2%+312000 -> 702895.78 | I51: =(I50-2400000)*31.2%+312000 -> 1004863.2 | J51: =(J50-2400000)*31.2%+312000 -> 1225170.3 | K51: =(K50-2400000)*31.2%+312000 -> 1547667.5 | L51: =(L50-2400000)*31.2%+312000 -> 1691543.9
A52: NET PROFIT AFTER TAX | B52: =B50-B51 -> 1857023.7 | C52: =C50-C51 -> 2115623.6 | D52: =D50-D51 -> 2082129.2 | E52: =E50-E51 -> 2037658.2 | F52: =F50-F51 -> 2158935.8 | G52: =G50-G51 -> 2351586.7 | H52: =H50-H51 -> 2949975.3 | I52: =I50-I51 -> 3615852.3 | ... L52: =L50-L51 -> 5130071.1
A53: NP RATIO (BEFORE DEP AND INT) | B53: 4.1614389 | C53: 5.3309405 | D53: 7.6148791 | E53: 7.2541806 | F53: 6.9934304 | G53: 6.9934304 | H53: 6.9934304 | I53: 6.9934304 | J53: 6.9934304 | K53: 6.9934304 | L53: 6.9934304
A54: NP RATIO (AFTER DEP AND INT) | B54: 1.1477912 | C54: 1.764267 | D54: 2.6227991 | E54: 2.5155614 | F54: 2.8272073 | G54: 2.8272073 | H54: 2.8272073 | I54: 2.8272073 | J54: 2.8272073 | K54: 2.8272073 | L54: 2.8272073
A57: =A24 -> M/S SHREE ENTERPRISES
...

Sheet SCH 2 cap
A3: ='FINAL REPORT'!A24:C24 -> M/S SHREE ENTERPRISES
A5: SCHEDULE 2: CAPITAL ACCOUNT
A7: Particulars | B7: ='FINAL REPORT'!B29 -> 31 Mar,26 | C7: ='FINAL REPORT'!C29 -> 31 Mar,27 | D7: ='FINAL REPORT'!D29 -> 31 Mar,28 | E7: ='FINAL REPORT'!E29 -> 31 Mar,29 | F7: ='FINAL REPORT'!F29 -> 32 Mar,30 | G7: ='FINAL REPORT'!G29 -> 32 Mar,31 | H7: ='FINAL REPORT'!H29 -> 33 Mar,32 | I7: ='FINAL REPORT'!I29 -> 33 Mar,33 | ... L7: ='FINAL REPORT'!L29 -> 34 Mar,36
B8: ='FINAL REPORT'!B30 -> PROVISIONAL | C8: ='FINAL REPORT'!C30 -> PROJECTED | D8: ='FINAL REPORT'!D30 -> PROJECTED | E8: ='FINAL REPORT'!E30 -> PROJECTED | F8: ='FINAL REPORT'!F30 -> PROJECTED | G8: ='FINAL REPORT'!G30 -> PROJECTED | H8: ='FINAL REPORT'!H30 -> PROJECTED | I8: ='FINAL REPORT'!I30 -> PROJECTED | ... L8: ='FINAL REPORT'!L30 -> PROJECTED
A9: Opening Bal | B9: 925750 | C9: =B17 -> 1991424.7 | D9: =C17 -> 3049236.5 | E9: =D17 -> 4090301.1 | F9: =E17 -> 5109130.2 | G9: =F17 -> 6188598.1 | H9: =G17 -> 7364391.5 | I9: =H17 -> 8544381.6 | J9: =I17 -> 9990722.5 | ... L9: =K17 -> 13556508
A11: Add: Net Profit during the year | B11: ='FINAL REPORT'!B52 -> 1857023.7 | C11: ='FINAL REPORT'!C52 -> 2115623.6 | D11: ='FINAL REPORT'!D52 -> 2082129.2 | E11: ='FINAL REPORT'!E52 -> 2037658.2 | F11: ='FINAL REPORT'!F52 -> 2158935.8 | G11: ='FINAL REPORT'!G52 -> 2351586.7 | H11: ='FINAL REPORT'!H52 -> 2949975.3 | I11: ='FINAL REPORT'!I52 -> 3615852.3 | ... L11: ='FINAL REPORT'!L52 -> 5130071.1
A12: Add: Other Income | B12: 0 | C12: 0 | D12: 0 | E12: 0 | F12: 0
B13: =B9+B11 -> 2782773.7 | C13: =C9+C11 -> 4107048.3 | D13: =D9+D11 -> 5131365.7 | E13: =E9+E11 -> 6127959.2 | F13: =F9+F11 -> 7268066 | G13: =G9+G11 -> 8540184.8 | H13: =H9+H11 -> 10314367 | I13: =I9+I11 -> 12160234 | ... L13: =L9+L11 -> 18686579
A15: Less: Drawings | B15: 791349 | C15: =C11*0.5 -> 1057811.8 | D15: =D11*0.5 -> 1041064.6 | E15: =E11*0.5 -> 1018829.1 | F15: =F11*0.5 -> 1079467.9 | G15: =G11*0.5 -> 1175793.4 | H15: =H11*0.6 -> 1769985.2 | I15: =I11*0.6 -> 2169511.4 | J15: =J11*0.6 -> 2460994.6 | K15: =K11*0.6 -> 2887683.1 | L15: =L11*0.6 -> 3078042.7
A17: Closing Bal | B17: =B13-B15 -> 1991424.7 | C17: =C13-C15 -> 3049236.5 | D17: =D13-D15 -> 4090301.1 | E17: =E13-E15 -> 5109130.2 | F17: =F13-F15 -> 6188598.1 | G17: =G13-G15 -> 7364391.5 | H17: =H13-H15 -> 8544381.6 | I17: =I13-I15 -> 9990722.5 | ... L17: =L13-L15 -> 15608536

Sheet SCH 2
A2: ='FINAL REPORT'!A24:C24 -> M/S SHREE ENTERPRISES
A4: SCHEDULE 1: ADMINISTRATION, SELLING AND DISTRIBUTION EXPENSES
A6: Particulars | B6: ='FINAL REPORT'!B29 -> 31 Mar,26 | C6: ='FINAL REPORT'!C29 -> 31 Mar,27 | D6: ='FINAL REPORT'!D29 -> 31 Mar,28 | E6: ='FINAL REPORT'!E29 -> 31 Mar,29 | F6: ='FINAL REPORT'!F29 -> 32 Mar,30 | G6: ='FINAL REPORT'!G29 -> 32 Mar,31 | H6: ='FINAL REPORT'!H29 -> 33 Mar,32 | I6: ='FINAL REPORT'!I29 -> 33 Mar,33 | ... L6: ='FINAL REPORT'!L29 -> 34 Mar,36
B7: ='FINAL REPORT'!B30 -> PROVISIONAL | C7: ='FINAL REPORT'!C30 -> PROJECTED | D7: ='FINAL REPORT'!D30 -> PROJECTED | E7: ='FINAL REPORT'!E30 -> PROJECTED | F7: ='FINAL REPORT'!F30 -> PROJECTED | G7: ='FINAL REPORT'!G30 -> PROJECTED | H7: ='FINAL REPORT'!H30 -> PROJECTED | I7: ='FINAL REPORT'!I30 -> PROJECTED | ... L7: ='FINAL REPORT'!L30 -> PROJECTED
A9: Travelling & Conveyance | B9: 12903 | C9: =B9*1.1 -> 14193.3 | D9: =C9*1.1 -> 15612.63 | E9: =D9*1.1 -> 17173.893 | F9: =E9*1.1 -> 18891.282 | G9: =F9*1.125 -> 21252.693 | H9: =G9*1.1 -> 23377.962 | I9: =H9*1.1 -> 25715.758 | J9: =I9*1.1 -> 28287.334 | K9: =J9*1.1 -> 31116.067 | L9: =K9*1.1 -> 34227.674
A10: Transport Charges | B10: 74214 | C10: =B10*1.1 -> 81635.4 | D10: =C10*1.08 -> 88166.232 | E10: =D10*1.08 -> 95219.531 | F10: =E10*1.08 -> 102837.09 | G10: =F10*1.08 -> 111064.06 | H10: =G10*1.08 -> 119949.19 | I10: =H10*1.08 -> 129545.12 | J10: =I10*1.08 -> 139908.73 | K10: =J10*1.08 -> 151101.43 | L10: =K10*1.08 -> 163189.54
A11: Loading & Unloading Charges | B11: =64005+12500 -> 76505 | C11: =B11*1.15 -> 87980.75 | D11: =C11*1.08 -> 95019.21 | E11: =D11*1.08 -> 102620.75 | F11: =E11*1.08 -> 110830.41 | G11: =F11*1.08 -> 119696.84 | H11: =G11*1.08 -> 129272.59 | I11: =H11*1.08 -> 139614.39 | J11: =I11*1.08 -> 150783.54 | K11: =J11*1.08 -> 162846.23 | L11: =K11*1.08 -> 175873.93
A12: Lunch & Refreshment | B12: 25750 | C12: =B12*1.15 -> 29612.5 | D12: =C12*1.1 -> 32573.75 | E12: =D12*1.1 -> 35831.125 | F12: =E12*1.1 -> 39414.238 | G12: =F12*1.16 -> 45720.516 | H12: =G12*1.1 -> 50292.567 | I12: =H12*1.1 -> 55321.824 | J12: =I12*1.1 -> 60854.006 | K12: =J12*1.1 -> 66939.407 | L12: =K12*1.1 -> 73633.347
A13: Insurance | B13: 13707 | C13: =B13*1.15 -> 15763.05 | D13: =C13*1.08 -> 17024.094 | E13: =D13*1.08 -> 18386.022 | F13: =E13*1.08 -> 19856.903 | G13: =F13*1.08 -> 21445.456 | H13: =G13*1.08 -> 23161.092 | I13: =H13*1.08 -> 25013.979 | J13: =I13*1.08 -> 27015.098 | K13: =J13*1.08 -> 29176.305 | L13: =K13*1.08 -> 31510.41
A14: Petrol Expenses | B14: 17632 | C14: =B14*1.15 -> 20276.8 | D14: =C14*1.09 -> 22101.712 | E14: =D14*1.09 -> 24090.866 | F14: =E14*1.09 -> 26259.044 | G14: =F14*1.09 -> 28622.358 | H14: =G14*1.09 -> 31198.37 | I14: =H14*1.09 -> 34006.224 | J14: =I14*1.09 -> 37066.784 | K14: =J14*1.09 -> 40402.794 | L14: =K14*1.09 -> 44039.046
A15: Office Expenses | B15: 117083 | C15: =B15*1.15 -> 134645.45 | D15: =C15*1.08 -> 145417.09 | E15: =D15*1.08 -> 157050.45 | F15: =E15*1.08 -> 169614.49 | G15: =F15*1.08 -> 183183.65 | H15: =G15*1.08 -> 197838.34 | I15: =H15*1.08 -> 213665.41 | J15: =I15*1.08 -> 230758.64 | K15: =J15*1.08 -> 249219.33 | L15: =K15*1.08 -> 269156.88
A16: Telephone & Communication Exp. | B16: 3850 | C16: =B16*1.15 -> 4427.5 | D16: =C16*1.1 -> 4870.25 | E16: =D16*1.1 -> 5357.275 | F16: =E16*1.1 -> 5893.0025 | G16: =F16*1.18 -> 6953.743 | H16: =G16*1.1 -> 7649.1172 | I16: =H16*1.1 -> 8414.029 | J16: =I16*1.1 -> 9255.4319 | K16: =J16*1.1 -> 10180.975 | L16: =K16*1.1 -> 11199.073
A17: Professional Fees | B17: 19235 | C17: =B17*1.15 -> 22120.25 | D17: =C17*1.1 -> 24332.275 | E17: =D17*1.1 -> 26765.503 | F17: =E17*1.1 -> 29442.053 | G17: =F17*1.19 -> 35036.043 | H17: =G17*1.1 -> 38539.647 | I17: =H17*1.1 -> 42393.612 | J17: =I17*1.1 -> 46632.973 | K17: =J17*1.1 -> 51296.27 | L17: =K17*1.1 -> 56425.897
A18: Printing & Stationery | B18: 5000 | C18: =B18*1.15 -> 5750 | D18: =C18*1.1 -> 6325 | E18: =D18*1.1 -> 6957.5 | F18: =E18*1.1 -> 7653.25 | G18: =F18*1.18 -> 9030.835 | H18: =G18*1.1 -> 9933.9185 | I18: =H18*1.1 -> 10927.31 | J18: =I18*1.1 -> 12020.041 | K18: =J18*1.1 -> 13222.046 | L18: =K18*1.1 -> 14544.25
A19: Electricity Expenses | B19: 80485 | C19: =B19*1.15 -> 92557.75 | D19: =C19*1.1 -> 101813.53 | E19: =D19*1.1 -> 111994.88 | F19: =E19*1.1 -> 123194.37 | G19: =F19*1.17 -> 144137.41 | H19: =G19*1.1 -> 158551.15 | I19: =H19*1.1 -> 174406.26 | J19: =I19*1.1 -> 191846.89 | K19: =J19*1.1 -> 211031.58 | L19: =K19*1.1 -> 232134.74
A20: Repairs and Maintenance | B20: 2480 | C20: =B20*1.15 -> 2852 | D20: =C20*1.1 -> 3137.2 | E20: =D20*1.1 -> 3450.92 | F20: =E20*1.1 -> 3796.012 | G20: =F20*1.15 -> 4365.4138 | H20: =G20*1.1 -> 4801.9552 | I20: =H20*1.1 -> 5282.1507 | J20: =I20*1.1 -> 5810.3658 | K20: =J20*1.1 -> 6391.4023 | L20: =K20*1.1 -> 7030.5426
A21: Shop Rent | B21: 11517 | C21: =B21*1.15 -> 13244.55 | D21: =C21*1.05 -> 13906.778 | E21: =D21*1.05 -> 14602.116 | F21: =E21*1.05 -> 15332.222 | G21: =F21*1.05 -> 16098.833 | H21: =G21*1.05 -> 16903.775 | I21: =H21*1.05 -> 17748.964 | J21: =I21*1.05 -> 18636.412 | K21: =J21*1.05 -> 19568.232 | L21: =K21*1.05 -> 20546.644
A22: Misc Expenses | B22: 1952694 | C22: =B22*1.15 -> 2245598.1 | D22: =C22*1.1 -> 2470157.9 | E22: =D22*1.1 -> 2717173.7 | F22: =E22*1.1 -> 2988891.1 | G22: =F22*1.18 -> 3526891.5 | H22: =G22*1.1 -> 3879580.6 | I22: =H22*1.1 -> 4267538.7 | J22: =I22*1.1 -> 4694292.5 | K22: =J22*1.1 -> 5163721.8 | L22: =K22*1.1 -> 5680094
B23: =SUM(B9:B22) -> 2413055 | C23: =SUM(C9:C22) -> 2770657.4 | D23: =SUM(D9:D22) -> 3040457.7 | E23: =SUM(E9:E22) -> 3336674.5 | F23: =SUM(F9:F22) -> 3661905.4 | G23: =SUM(G9:G22) -> 4273499.3 | H23: =SUM(H9:H22) -> 4691050.3 | I23: =SUM(I9:I22) -> 5149593.7 | ... L23: =SUM(L9:L22) -> 6813605.9

Sheet EMI
B2: EMI CALCULATOR | I2: INSTRUCTION
B4: LOAN AMOUNT | D4: 4000000 | F4: FILL UP | I4: Please Fill Up Only Loan Amount, Rate Per Annum,and Nos. of Installments it will Automatically shows you the details of EMIs
B6: RATE OF INTEREST PER ANNUM | D6: 0.086 | F6: FILL UP
B8: RATE OF INTEREST PER MONTH | D8: =D6/12 -> 0.0071666667
B10: NO OF INSTALLMENT | D10: 120 | F10: FILL UP
D11: 62
B12: EMI | D12: =-PMT(D8,D10,D4) -> 49808.462
B14: CALCULATION OF DETAILS OF EMI
B16: MONTHS | C16: EMI | D16: INTEREST | E16: PRINCIPAL REPAYMENT | F16: OST PRINCIPAL | J16: Interest
B17: 0 | F17: =D4 -> 4000000
B18: 1 | C18: =D12 -> 49808.462 | D18: =F17*D8 -> 28666.667 | E18: =C18-D18 -> 21141.796 | F18: =F17-E18 -> 3978858.2
B19: 2 | C19: =D12 -> 49808.462 | D19: =F18*D8 -> 28515.15 | E19: =C19-D19 -> 21293.312 | F19: =F18-E19 -> 3957564.9
B20: 3 | C20: =D12 -> 49808.462 | D20: =F19*D8 -> 28362.548 | E20: =C20-D20 -> 21445.914 | F20: =F19-E20 -> 3936119
B21: 4 | C21: =D12 -> 49808.462 | D21: =F20*D8 -> 28208.853 | E21: =C21-D21 -> 21599.61 | F21: =F20-E21 -> 3914519.4
B22: 5 | C22: =D12 -> 49808.462 | D22: =F21*D8 -> 28054.055 | E22: =C22-D22 -> 21754.407 | F22: =F21-E22 -> 3892765
B23: 6 | C23: =D12 -> 49808.462 | D23: =F22*D8 -> 27898.149 | E23: =C23-D23 -> 21910.313 | F23: =F22-E23 -> 3870854.6 | J23: =SUM(D18:D23) -> 169705.42 | K23: 46447
B24: 7 | C24: =D12 -> 49808.462 | D24: =F23*D8 -> 27741.125 | E24: =C24-D24 -> 22067.337 | F24: =F23-E24 -> 3848787.3
B25: 8 | C25: =D12 -> 49808.462 | D25: =F24*D8 -> 27582.976 | E25: =C25-D25 -> 22225.487 | F25: =F24-E25 -> 3826561.8
B26: 9 | C26: =D12 -> 49808.462 | D26: =F25*D8 -> 27423.693 | E26: =C26-D26 -> 22384.769 | F26: =F25-E26 -> 3804177.1
B27: 10 | C27: =D12 -> 49808.462 | D27: =F26*D8 -> 27263.269 | E27: =C27-D27 -> 22545.193 | F27: =F26-E27 -> 3781631.9
B28: 11 | C28: =D12 -> 49808.462 | D28: =F27*D8 -> 27101.695 | E28: =C28-D28 -> 22706.767 | F28: =F27-E28 -> 3758925.1
B29: 12 | C29: =D12 -> 49808.462 | D29: =F28*D8 -> 26938.963 | E29: =C29-D29 -> 22869.499 | F29: =F28-E29 -> 3736055.6 | G29: 1 | I29: =SUM(D18:D29) -> 333757.14
B30: 13 | C30: =D12 -> 49808.462 | D30: =F29*D8 -> 26775.065 | E30: =C30-D30 -> 23033.397 | F30: =F29-E30 -> 3713022.2
B31: 14 | C31: =D12 -> 49808.462 | D31: =F30*D8 -> 26609.992 | E31: =C31-D31 -> 23198.47 | F31: =F30-E31 -> 3689823.7
B32: 15 | C32: =D12 -> 49808.462 | D32: =F31*D8 -> 26443.737 | E32: =C32-D32 -> 23364.726 | F32: =F31-E32 -> 3666459
B33: 16 | C33: =D12 -> 49808.462 | D33: =F32*D8 -> 26276.29 | E33: =C33-D33 -> 23532.173 | F33: =F32-E33 -> 3642926.8
B34: 17 | C34: =D12 -> 49808.462 | D34: =F33*D8 -> 26107.642 | E34: =C34-D34 -> 23700.82 | F34: =F33-E34 -> 3619226
B35: 18 | C35: =D12 -> 49808.462 | D35: =F34*D8 -> 25937.786 | E35: =C35-D35 -> 23870.676 | F35: =F34-E35 -> 3595355.3 | J35: =SUM(D24:D35) -> 322202.23 | K35: 46813
B36: 19 | C36: =D12 -> 49808.462 | D36: =F35*D8 -> 25766.713 | E36: =C36-D36 -> 24041.749 | F36: =F35-E36 -> 3571313.6
B37: 20 | C37: =D12 -> 49808.462 | D37: =F36*D8 -> 25594.414 | E37: =C37-D37 -> 24214.048 | F37: =F36-E37 -> 3547099.5
B38: 21 | C38: =D12 -> 49808.462 | D38: =F37*D8 -> 25420.88 | E38: =C38-D38 -> 24387.582 | F38: =F37-E38 -> 3522712
B39: 22 | C39: =D12 -> 49808.462 | D39: =F38*D8 -> 25246.102 | E39: =C39-D39 -> 24562.36 | F39: =F38-E39 -> 3498149.6
B40: 23 | C40: =D12 -> 49808.462 | D40: =F39*D8 -> 25070.072 | E40: =C40-D40 -> 24738.39 | F40: =F39-E40 -> 3473411.2
B41: 24 | C41: =D12 -> 49808.462 | D41: =F40*D8 -> 24892.78 | E41: =C41-D41 -> 24915.682 | F41: =F40-E41 -> 3448495.5 | G41: 2 | I41: =SUM(D30:D41) -> 310141.47
B42: 25 | C42: =D12 -> 49808.462 | D42: =F41*D8 -> 24714.218 | E42: =C42-D42 -> 25094.244 | F42: =F41-E42 -> 3423401.3
B43: 26 | C43: =D12 -> 49808.462 | D43: =F42*D8 -> 24534.376 | E43: =C43-D43 -> 25274.086 | F43: =F42-E43 -> 3398127.2
B44: 27 | C44: =D12 -> 49808.462 | D44: =F43*D8 -> 24353.245 | E44: =C44-D44 -> 25455.217 | F44: =F43-E44 -> 3372672
B45: 28 | C45: =D12 -> 49808.462 | D45: =F44*D8 -> 24170.816 | E45: =C45-D45 -> 25637.646 | F45: =F44-E45 -> 3347034.3
B46: 29 | C46: =D12 -> 49808.462 | D46: =F45*D8 -> 23987.079 | E46: =C46-D46 -> 25821.383 | F46: =F45-E46 -> 3321212.9
B47: 30 | C47: =D12 -> 49808.462 | D47: =F46*D8 -> 23802.026 | E47: =C47-D47 -> 26006.436 | F47: =F46-E47 -> 3295206.5 | J47: =SUM(D36:D47) -> 297552.72 | K47: 47178
...

Sheet OD
B5: M/S SHREE ENTERPRISES
B10: Year | C10: Opening OD Balance | D10: Principal Repayment | E10: Interest
B11: 2026-27 | C11: 3323350 | D11: 275350 | E11: =C11*9.5% -> 315718.25
B12: 2027-28 | C12: =C11-D11 -> 3048000 | D12: 291457 | E12: =C12*9.5% -> 289560
B13: 2028-29 | C13: =C12-D12 -> 2756543 | D13: 310750 | E13: =C13*9.5% -> 261871.58
B14: 2029-30 | C14: =C13-D13 -> 2445793 | D14: 340350 | E14: =C14*9.5% -> 232350.33
B15: 2030-31 | C15: =C14-D15 -> 2085043 | D15: 360750 | E15: =C15*9.5% -> 198079.08
B16: 2031-32 | C16: =C15-D15 -> 1724293 | D16: 380750 | E16: =C16*9.5% -> 163807.83
B17: 2032-33 | C17: =C16-D16 -> 1343543 | D17: 400150 | E17: =C17*9.5% -> 127636.59
B18: 2033-34 | C18: =C17-D17 -> 943393 | D18: 425750 | E18: =C18*9.5% -> 89622.335
B19: 2034-35 | C19: =C18-D18 -> 517643 | D19: 448750 | E19: =C19*9.5% -> 49176.085
B20: 2035-36 | C20: =D19 -> 448750 | D20: =C11-SUM(D11:D19) -> 89293 | E20: =C20*9.5% -> 42631.25
C21: =SUM(C11:C20) -> 18636351 | D21: =SUM(D11:D20) -> 3323350 | E21: =SUM(E11:E20) -> 1770453.3

Sheet Sheet1
B2: EMI CALCULATOR | I2: INSTRUCTION
B4: LOAN AMOUNT | D4: 765304 | F4: FILL UP | I4: Please Fill Up Only Loan Amount, Rate Per Annum,and Nos. of Installments it will Automatically shows you the details of EMIs
B6: RATE OF INTEREST PER ANNUM | D6: 0.13 | F6: FILL UP
B8: RATE OF INTEREST PER MONTH | D8: =D6/12 -> 0.010833333
B10: NO OF INSTALLMENT | D10: 24 | F10: FILL UP
D11: 62
B12: EMI | D12: =-PMT(D8,D10,D4) -> 36383.947
B14: CALCULATION OF DETAILS OF EMI
B16: MONTHS | C16: EMI | D16: INTEREST | E16: PRINCIPAL REPAYMENT | F16: OST PRINCIPAL
B17: 0 | F17: =D4 -> 765304
B18: 1 | C18: =D12 -> 36383.947 | D18: =F17*D8 -> 8290.7933 | E18: =C18-D18 -> 28093.154 | F18: =F17-E18 -> 737210.85
B19: 2 | C19: =D12 -> 36383.947 | D19: =F18*D8 -> 7986.4508 | E19: =C19-D19 -> 28397.496 | F19: =F18-E19 -> 708813.35
B20: 3 | C20: =D12 -> 36383.947 | D20: =F19*D8 -> 7678.8113 | E20: =C20-D20 -> 28705.136 | F20: =F19-E20 -> 680108.21 | G20: 44986 | I20: =SUM(D18:D20) -> 23956.055
B21: 4 | C21: =D12 -> 36383.947 | D21: =F20*D8 -> 7367.839 | E21: =C21-D21 -> 29016.108 | F21: =F20-E21 -> 651092.11
B22: 5 | C22: =D12 -> 36383.947 | D22: =F21*D8 -> 7053.4978 | E22: =C22-D22 -> 29330.449 | F22: =F21-E22 -> 621761.66
B23: 6 | C23: =D12 -> 36383.947 | D23: =F22*D8 -> 6735.7513 | E23: =C23-D23 -> 29648.196 | F23: =F22-E23 -> 592113.46
B24: 7 | C24: =D12 -> 36383.947 | D24: =F23*D8 -> 6414.5625 | E24: =C24-D24 -> 29969.384 | F24: =F23-E24 -> 562144.08
B25: 8 | C25: =D12 -> 36383.947 | D25: =F24*D8 -> 6089.8942 | E25: =C25-D25 -> 30294.053 | F25: =F24-E25 -> 531850.02
B26: 9 | C26: =D12 -> 36383.947 | D26: =F25*D8 -> 5761.7086 | E26: =C26-D26 -> 30622.238 | F26: =F25-E26 -> 501227.79
B27: 10 | C27: =D12 -> 36383.947 | D27: =F26*D8 -> 5429.9677 | E27: =C27-D27 -> 30953.979 | F27: =F26-E27 -> 470273.81
B28: 11 | C28: =D12 -> 36383.947 | D28: =F27*D8 -> 5094.6329 | E28: =C28-D28 -> 31289.314 | F28: =F27-E28 -> 438984.49
B29: 12 | C29: =D12 -> 36383.947 | D29: =F28*D8 -> 4755.6653 | E29: =C29-D29 -> 31628.282 | F29: =F28-E29 -> 407356.21
B30: 13 | C30: =D12 -> 36383.947 | D30: =F29*D8 -> 4413.0256 | E30: =C30-D30 -> 31970.921 | F30: =F29-E30 -> 375385.29
B31: 14 | C31: =D12 -> 36383.947 | D31: =F30*D8 -> 4066.674 | E31: =C31-D31 -> 32317.273 | F31: =F30-E31 -> 343068.02
B32: 15 | C32: =D12 -> 36383.947 | D32: =F31*D8 -> 3716.5702 | E32: =C32-D32 -> 32667.377 | F32: =F31-E32 -> 310400.64 | G32: 45352 | I32: =SUM(D21:D32) -> 66899.789
B33: 16 | C33: =D12 -> 36383.947 | D33: =F32*D8 -> 3362.6736 | E33: =C33-D33 -> 33021.273 | F33: =F32-E33 -> 277379.37
B34: 17 | C34: =D12 -> 36383.947 | D34: =F33*D8 -> 3004.9431 | E34: =C34-D34 -> 33379.004 | F34: =F33-E34 -> 244000.36
B35: 18 | C35: =D12 -> 36383.947 | D35: =F34*D8 -> 2643.3373 | E35: =C35-D35 -> 33740.61 | F35: =F34-E35 -> 210259.75
B36: 19 | C36: =D12 -> 36383.947 | D36: =F35*D8 -> 2277.814 | E36: =C36-D36 -> 34106.133 | F36: =F35-E36 -> 176153.62
B37: 20 | C37: =D12 -> 36383.947 | D37: =F36*D8 -> 1908.3309 | E37: =C37-D37 -> 34475.616 | F37: =F36-E37 -> 141678
B38: 21 | C38: =D12 -> 36383.947 | D38: =F37*D8 -> 1534.845 | E38: =C38-D38 -> 34849.102 | F38: =F37-E38 -> 106828.9
B39: 22 | C39: =D12 -> 36383.947 | D39: =F38*D8 -> 1157.3131 | E39: =C39-D39 -> 35226.634 | F39: =F38-E39 -> 71602.268
B40: 23 | C40: =D12 -> 36383.947 | D40: =F39*D8 -> 775.69123 | E40: =C40-D40 -> 35608.256 | F40: =F39-E40 -> 35994.012
B41: 24 | C41: =D12 -> 36383.947 | D41: =F40*D8 -> 389.93513 | E41: =C41-D41 -> 35994.012 | F41: =F40-E41 -> 1.3824319e-10
B42: 25 | C42: =D12 -> 36383.947 | D42: =F41*D8 -> 1.4976346e-12 | E42: =C42-D42 -> 36383.947 | F42: =F41-E42 -> -36383.947
B43: 26 | C43: =D12 -> 36383.947 | D43: =F42*D8 -> -394.15943 | E43: =C43-D43 -> 36778.106 | F43: =F42-E43 -> -73162.053
B44: 27 | C44: =D12 -> 36383.947 | D44: =F43*D8 -> -792.58891 | E44: =C44-D44 -> 37176.536 | F44: =F43-E44 -> -110338.59 | G44: 45717 | I44: =SUM(D33:D44) -> 15868.135
B45: 28 | C45: =D12 -> 36383.947 | D45: =F44*D8 -> -1195.3347 | E45: =C45-D45 -> 37579.282 | F45: =F44-E45 -> -147917.87
B46: 29 | C46: =D12 -> 36383.947 | D46: =F45*D8 -> -1602.4436 | E46: =C46-D46 -> 37986.391 | F46: =F45-E46 -> -185904.26
B47: 30 | C47: =D12 -> 36383.947 | D47: =F46*D8 -> -2013.9628 | E47: =C47-D47 -> 38397.91 | F47: =F46-E47 -> -224302.17
...
